const x = 0

try{
    x =1
}catch(err){
    console.log('Um erro ocorreu: %s', err)
}